sample_out/50406838879770.txt
FMS 36.2
PNC-Q 24.82
MTEC 10.14
JELD 16.61
FSZ 47.27
AMTD 55.56
RFP 9.11
YEXT 14.99
GMED 44.05
AUMN 0.33
ORMP 3.42
EZPW 9.37
EVOP 24.78
TBBK 8.61
USCI 38.77
RBS 6.41
CTG 4.3
AFMD 3.21
DRIP 10.75
JTD 14.97
VYM 81.54
CBZ 19.6
ECA 6.885
SBFGP 18.22
SPEM 34.55
UNG 25.5
FII 26.27
WCC 53.49
EMX 1.14
ESL 121.49
BH.A 657.0
SDG 56.28
CTB 34.09
VET 24.14
VMI 126.97
IYJ 141.16
MBIO 3.35
VOX 78.3
XBIO 2.1
EMLP 23.28
DCP 33.95
MPAA 20.1
NVEC 93.1
JHSC 25.03
LMAT 23.76
RWM 42.59
ESNT 38.47
BGS 26.1
FICO 216.48
XELA 3.55
PERI 3.28
SPHD 40.6
TLC 6.5
HLIT 5.1
AMID 4.08
DK 32.41
VONV 103.39
HR 31.76
CACI 158.15
GNR 44.51
TBPH 25.07
DRW 30.7
SFE 9.5
FENC 6.44
TRTN 35.61
CCLP 2.54
AYX 69.58
MDC 30.32
UJPY 25.3
CBRE 44.78
GPP 15.27
AGM 71.33
BLX 18.6
ISIG 1.18
CACG 28.715
CNDT 12.47
MNTX 6.81
VTC 81.32
EWG 26.75
IAGG 52.48
GLL 70.19
MSC 13.4
OGS 80.06
EPAM 139.15
CIGI 61.13
MXWL 2.98
KTF 10.89
AGO 40.22
AMBR 8.34
OIBR.C 1.63
FUV 3.03
CRS 44.45
BIOS 3.6
QSR 62.0
AMRWW 0.105
UFPI 29.24
PHB 18.27
IUSB 49.54
NOG 2.54
GWR 78.45
CPA 93.75
OPTN 6.11
SRE-B 100.06
ZF 9.2
FDEU 14.02
GLV 10.69
QTWO 57.34
AAON 35.54
SKIS 4.55
CPT 96.215
PII 83.87
BSIG 12.41
DHIL 156.52
FSK 6.34
HPE 15.505
ATIS 0.3052
REN 33.3
OZK 31.59
BTN 1.55
XLNX 111.28
GVAL 22.83
OLED 102.3
AMCI 9.68
GSIT 7.75
PUMP 16.16
YINN 21.37
SCE-J 20.36
GNL-A 24.53
KMI 17.99
DG 115.06
SMDV 56.79
CPRT 49.75
QGEN 37.1
QARP 24.94
CLNC 16.34
WHLRP 10.27
SFUN 1.67
RECN 16.56
GARS 7.39
CVA 15.73
URTH 84.01
USPH 105.89
ELF 8.43
ATHM 70.065
ERIC 8.885
CFFI 49.63
BPOPN 25.71
WVVI 7.06
MILN 21.66
VVV 22.28
BBRE 79.98
ANIP 53.76
XSW 82.84
RYTM 25.815
DIV 23.55
LMNR 21.63
NITE 12.92
PVTL 18.26
SPLV 48.84
CGIX 0.2452
ALNA 7.55
IMAX 20.82
DUK 85.76
RYB 7.33
CHEF 32.07
EEA 8.16
PSA-C 23.145
CCS 21.69
BR 99.76
COHU 17.61
MGRC 49.54
ETJ 8.505
GXG 8.865
LECO 85.92
THM 0.6197
MDCA 2.93
CLIX 47.16
VDE 85.01
DPG 13.83
QYLD 21.8
ADSK 142.61
NYT 26.02
NSYS 4.17
PCG 13.79
VMW 145.8
INSM 24.32
ORC 6.99
CBMB 12.78
CNS 37.09
CPE 8.17
FSCT 29.65
HSC 20.97
CNXM 17.38
FATE 14.1
LCNB 16.39
LXFT 57.69
FOXA 49.04
WEYS 27.11
EFR 13.07
WATT 7.31
HDSN 1.21
ALB 78.97
ELLI 72.8
GEN 1.5
WSC 10.04
NFRA 46.6
JXI 50.65
CIG 3.7
DLPN 1.42
FRT 130.93
LEO 7.59
ALDR 13.67
UCBI 26.17
MFA-B 24.77
AQN 10.86
DSM 7.34
IVR-A 24.98
FNLC 26.13
WMC 9.58
CASY 128.87
PCMI 21.13
MOBL 4.765
BSTC 64.11
SSRM 13.39
INSI 18.5
AUTO 3.09
CCR 18.45
GDO 15.98
RDVT 7.63
ON 19.66
SON 56.17
AAME 2.53
USO 11.43
CYH 3.69
CS 12.35
SNV 36.13
VTVT 2.73
IVR-B 25.59
GDV-A 25.72
PSAU 18.4
KIM-L 21.39
EPE 0.7007
HEES 26.15
ISSC 2.25
DEUS 30.62
EV 38.05
USEG 0.871
CLNY-J 20.39
WFC-Q 25.35
IBDQ 24.2
BIP 38.57
HALO 16.0
IPAR 66.67
TOWR 29.085
ADOM 0.2505
IPLDP 24.9
DEX 9.35
CPST 0.8497
TNK 1.015
GRC 33.48
VOOV 104.5
PSCI 60.84
WHLM 5.85
WNEB 9.32
PFFA 23.805
KONA 1.11
AMAG 15.18
AUPH 6.37
YLCO 12.21
DAVA 24.16
CC 35.51
PDFS 10.32
TISA 0.52
AYTU 1.18
FINX 24.84
YVR 2.35
VOC 4.77
UIS 12.97
TMO 241.07
YRCW 5.84
UWN 2.47
TPH 12.36
VERU 1.48
WMB 26.8
XHE 74.61
COWNZ 24.92
MTEX 18.86
ETP-D 24.6
CSU 7.1
HLNE 36.07
DJP 22.5
OXY 66.71
BDC 52.41
FMHI 50.23
CDR-B 24.46
MSA 97.65
DGII 11.39
SAIC 67.41
PMBC 7.94
CIZ 31.45
UPWK 18.91
RMAX 38.91
KALV 17.4
BAX 71.185
CCD 19.5
PRO 33.94
STNLW 0.85
XNET 3.405
FELP 3.35
ERJ 20.73
DDWM 27.52
RZG 113.33
EMCB 69.57
NCTY 1.38
MMT 5.56
TIF 87.36
BMI 51.52
TOUR 4.4
SLNO 1.72
SBLKZ 25.04
CCMP 100.9
PSC 30.03
XRX 27.91
OMFL 26.45
VLGEA 26.58
DBP 37.16
LTPZ 62.51
IVAC 5.31
XHR 18.52
ATHN 134.57
FOE 16.42
CURE 50.89
FPAY 0.79
DRAD 0.7
JMEI 2.605
TNXP 2.0
DRRX 0.5998
IGEB 48.16
SSW-H 23.25
NIU 7.6
FTXD 21.54
BRSS 29.35
OSG 1.885
MGLN 65.91
XLU 53.32
NPTN 7.04
DNLI 18.655
DAIO 5.84
HYLB 48.66
REGL 54.69
IDEV 52.04
UMBF 62.92
SLYG 58.05
GRNQ 3.2
PPT 4.94
OAK-B 24.25
CHY 10.98
NOA 10.24
RWW 63.0
LENS 0.44
MDYV 49.21
DLS 64.32
NESR 7.75
HTLD 20.33
KNL 19.61
JLL 139.62
SBFG 18.4
NAVG 69.785
GSLC 53.44
KBE 43.07
C-N 26.28
RFEU 56.47
CRL 121.03
JILL 6.0
OHGI 0.1221
PHT 8.5
MXL 19.15
CERS 5.685
GLMD 7.31
DVD 1.98
CBD 25.96
HIL 3.33
EMO 9.69
HST 18.13
DVN 27.28
SPXU 38.45
AIMC 29.31
TRT 2.95
NEE 172.85
EOLS 15.29
FAN 12.58
CENX 8.69
RUBY 13.8
EDD 6.64
VHT 166.21
TNC 58.16
SALM 2.76
CHAP 7.97
LXFR 19.9
ORLY 343.53
RGR 53.48
WGP 32.79
APO-A 24.52
DES 26.88
WSTL 2.16
GFI 3.94
EES 35.57
USMF 27.77
ALD 44.03
AMN 64.34
NEO 16.37
BDC-B 71.45
ALDX 8.4
WOR 36.71
TWOU 55.92
PFL 11.31
AGCO 63.55
MGA 52.02
BKK 14.93
CEI 0.4661
EPHE 34.2
AVAL 6.805
DWSH 25.9
AFIF 9.94
BPFH 11.73
ACRE 14.33
IYH 186.72
TEL 79.34
PRCP 8.13
DRN 22.55
SPOK 13.69
EDV 112.29
BWA 40.34
PAHC 31.06
SCOR 19.22
EOT 20.83
EXFO 3.28
STL-A 26.5
VRSK 116.94
FLR 35.87
ALLT 6.74
EPR 72.35
HTY 6.9
CBH 8.76
ICLR 137.56
RFDI 55.27
TECS 22.46
DD-B 99.97
CABO 858.17
QUOT 9.985
SPB 54.26
UAL 87.02
PRTA 11.63
NWFL 29.39
LYV 52.55
AFSI-C 8.3
NPV 12.04
HEQ 14.36
ARNC 18.74
VSEC 31.87
AME 71.79
KMT 37.46
PRTO 2.6
JG 7.71
BAH 48.14
MOXC 0.5201
MTUM 104.82
REGI 27.95
GLTR 64.92
FULT 16.28
PSJ 81.0
NUV 9.61
CI 197.25
ANH 4.49
ACER 23.7
CYTR 0.565
ATSG 22.92
JKE 168.9
ENB 36.39
IPHS 29.83
VIXM 24.26
FLWS 13.15
COPX 19.79
C-K 26.73
IESC 16.61
ATISW 0.08
APDN 0.441
VRTS 85.49
IQLT 27.46
SPXC 28.9
EVFM 3.44
INDL 58.25
DTV 53.3
PYPL 92.14
DCOM 19.57
EVA 30.11
FCBP 21.37
TDE 24.99
GRA 71.05
EPC 38.96
JAKK 1.8
ASTC 5.02
BSE 12.43
UG 19.44
DATA 126.05
FN 54.74
COUP 78.93
CTRN 20.59
DOG 57.5
ERF 8.81
DXF 3.02
ENT 2.62
GSBD 20.285
PDEX 14.65
FOLD 11.25
JAZZ 125.525
TRTX 19.47
SFST 36.76
TDW+A 2.22
BSCE 25.15
PZD 40.03
FTFT 0.79
ZG 32.65
SCO 20.34
HOFT 28.0
KGJI 0.77
SPWR 5.63
NRT 6.3
SOLOW 0.4
KOP 22.84
KRC 70.15
TOTL 47.48
JDST 42.2
IGOV 48.89
CVLY 22.1
TTS 7.465
WBC 113.22
COWN 15.54
FTSV 14.52
MITT 17.86
RWR 94.75
CHMG 42.17
GASL 8.18
RJI 5.24
TENB 26.83
BRACR 0.32
AIHS 3.95
MSI 116.06
WBIG 23.34
MARPS 2.0
IPG 22.63
JPI 21.83
MSCI 161.8
RNR 137.12
ETON 6.2
FEX 56.29
MS-K 25.44
PLND 17.14
HSDT 7.43
MLM 177.9
SRV 9.88
TRI 51.56
STND 31.2
HUBG 44.0
EDRY 7.66
LLL 199.06
IYF 115.68
EXTR 7.46
CORT 11.68
NSP 104.52
GLP 19.26
CHSCP 28.95
BGIO 8.72
ENOB 6.01
HL 2.55
PHCF 4.9
TRQ 1.655
DFFN 2.16
SEND 49.45
CCOI 46.98
MIDU 36.46
KNX 32.89
TAIT 2.0
MODN 14.18
KMB 107.91
HYHG 65.07
APM 13.21
OKTA 78.36
HYLS 46.78
ARTNA 34.465
IGSB 52.08
NULG 32.16
FIF 14.96
LOGI 35.78
DLTR 95.49
RETA 75.79
ECOL 62.71
MPB 23.99
CTL 14.9
ALTY 14.46
NAII 11.04
MBOT 8.4
FDUSL 25.45
TVTY 21.88
BFR 13.42
ATOM 3.94
NOC 280.78
VTSI 3.99
SBUX 67.59
FMAO 31.15
MITT-B 25.315
FET 4.93
EWH 24.28
NTRS 89.2
SDIV 18.99
SONO 11.36
CHN 18.9
VLRS 7.35
SLY 65.3
STL 19.4
AGYS 17.78
FAM 9.94
NCLH 50.37
ULH 20.2
ALG 85.92
NNVC 0.31
THRM 40.9
BAF 13.25
UTSL 26.79
BH 129.25
EDZ 47.28
GLW 33.42
WWE 82.09
MORT 23.13
TRK 15.93
SRG-A 23.25
SRC 38.97
FCNCA 417.72
BHK 12.92
TRGP 42.84
SBNY 126.63
CWK 16.42
ET 14.53
SIGA 6.59
TYD 42.81
EARS 0.43
FREL 24.65
FNY 40.29
SMMF 23.28
SPG 181.49
SNN 37.68
RHI 64.97
NBN 20.09
SSNC 50.12
CNP-B 52.58
THFF 41.34
IYR 82.35
COR 96.825
INFU 3.75
NGVC 13.3
NEWTI 25.58
AGRX 0.8307
BB 8.01
FSM 3.83
VGZ 0.66
HWKN 41.26
SNBR 34.98
ITCB 14.82
PB 71.26
AOS 47.19
SRTY 29.56
MOSY 0.1799
IBDR 23.54
DEMG 24.78
VRRM 10.27
IAI 60.48
OPNT 14.725
LUV 57.22
POOL 150.59
APPN 31.48
REV 25.66
EYES 0.82
AEO 21.11
MEIP 2.68
CFBI 10.66
TYME 2.73
NOMD 17.91
NWE 62.49
BSJN 25.55
BIF 10.63
DPST 47.2
BHVN 38.2
ROAN 10.78
DFS 67.42
BCS 8.44
KSA 32.0
PSA-E 22.17
OSMT 7.92
MYE 16.04
LOGC 8.62
AMRX 11.87
SELF 3.97
AGR 48.97
GMLP 13.09
BOLD 23.27
BOCH 10.97
OPINI 23.62
NRIM 33.0
IOSP 68.47
MCRB 6.07
HABT 10.25
MRC 15.49
SWP 94.11
NVGS 9.45
TAN 22.34
CDAY 39.78
KALA 5.23
CKPT 3.85
VVR 4.08
CEA 30.75
AXTI 3.98
WSBC 41.46
BMLP 47.2
FRC-D 24.18
DBX 23.71
HCFT 3.37
TD 55.72
GWRS 9.53
MGP 30.8
PIHPP 22.0
XHB 35.53
DDIV 22.74
CVM 2.87
LONE 4.78
GLO 9.08
PFI 31.08
HYAC 10.17
BOMN 24.94
FMN 13.03
BOKF 85.29
FWONK 30.655
MASI 121.88
IEF 104.02
AIG+ 7.02
ABEO 6.53
MCHI 57.88
VGSH 60.125
PCG-C 16.64
TMCX 10.08
IXG 61.59
ANSS 160.58
PCOM 10.63
SCHM 52.54
QNST 18.37
IDXX 205.69
HIX 6.335
PHIOW 0.025
ETR 86.66
FCEF 20.36
GLUU 9.4
PKG 91.68
TECD 94.71
F 8.61
LZB 29.1
XCEM 25.87
UNB 47.2
PBI 7.17
MDU 25.22
SAP 101.4
ROKU 43.7
DOGZ 3.67
