sample_out/54006848066489.txt
FMS 36.57
PNC-Q 24.84
MTEC 10.14
JELD 16.99
FSZ 47.27
AMTD 55.8
RFP 9.23
YEXT 15.14
GMED 44.57
AUMN 0.358
ORMP 3.32
EZPW 9.49
EVOP 25.12
TBBK 8.58
USCI 38.85
RBS 6.49
CTG 4.29
AFMD 3.28
DRIP 10.41
JTD 14.97
VYM 82.1
CBZ 19.77
ECA 6.995
SBFGP 18.22
SPEM 35.03
UNG 25.525
FII 26.3
WCC 54.16
EMX 1.14
ESL 121.57
BH.A 657.0
SDG 56.65
CTB 34.41
VET 24.56
VMI 129.21
IYJ 142.98
MBIO 3.36
VOX 78.9
XBIO 2.1
EMLP 23.48
DCP 34.25
MPAA 20.22
NVEC 93.45
JHSC 25.03
LMAT 23.77
BNY 12.47
ESNT 39.03
BGS 26.03
FICO 218.2
XELA 3.59
PERI 3.34
SPHD 40.91
TLC 6.5
HLIT 5.16
AMID 4.14
DK 32.62
VONV 104.39
HR 32.01
CACI 159.47
GNR 45.07
TBPH 25.37
DRW 31.0
SFE 9.52
FMHI 50.23
FENC 6.425
TRTN 36.27
CCLP 2.6
AYX 71.04
MDC 31.06
UJPY 25.3
CBRE 45.35
GPP 15.34
RYE 49.91
AGM 72.3
BLX 18.7
ISIG 1.18
CACG 29.0
CNDT 12.69
MNTX 6.99
VTC 81.32
EWG 27.06
IAGG 52.48
GLL 69.07
MSC 13.4
OGS 81.2
EPAM 141.21
CIGI 61.7
MXWL 2.99
KTF 10.89
AGO 40.46
STT-D 26.4
AMBR 8.43
OIBR.C 1.65
FUV 3.05
CRS 45.29
BIOS 3.61
QSR 62.675
AMRWW 0.105
UFPI 29.75
PHB 18.37
IUSB 49.64
NOG 2.58
GWR 79.46
CPA 96.035
OPTN 6.125
SRE-B 100.43
ZF 9.2
FDEU 14.06
GLV 10.73
QTWO 58.08
AAON 36.2
GOLF 23.04
CPT 96.78
PII 84.49
BSIG 12.46
DVEM 30.93
DHIL 155.3
FSK 6.37
HPE 15.66
ATIS 0.305
REN 33.26
UBG 33.29
OZK 31.73
BTN 1.55
XLNX 112.96
GVAL 22.83
OLED 102.55
AMCI 9.68
GSIT 7.81
PUMP 16.31
YINN 22.23
SCE-J 20.36
GNL-A 24.5
KMI 18.16
DG 115.88
SMDV 57.04
CPRT 50.3
QGEN 37.58
TILT 108.76
QARP 24.94
CLNC 16.46
WHLRP 10.29
SFUN 1.695
RECN 16.6
GARS 7.39
CVA 15.82
URTH 84.45
USPH 106.52
ELF 8.47
ATHM 70.8
ERIC 8.985
CFFI 50.17
BPOPN 25.99
WVVI 7.06
MILN 21.66
VVV 22.49
BBRE 79.98
ANIP 54.21
XSW 83.4
RYTM 26.35
DIV 23.64
LMNR 21.64
NITE 13.19
PVTL 18.495
SPLV 49.26
CGIX 0.2514
ALNA 7.57
IMAX 20.96
DUK 86.5
RYB 7.19
CHEF 32.41
EEA 8.24
PSA-C 23.145
CCS 22.42
BR 100.7
COHU 17.67
MGRC 50.04
ETJ 8.575
GXG 8.9
LECO 87.7
THM 0.6165
MDCA 2.97
CLIX 47.16
VDE 85.96
DPG 13.83
QYLD 21.8
ADSK 145.28
NYT 26.125
NSYS 4.17
PCG 13.57
VMW 147.23
INSM 24.52
ORC 7.005
CBMB 12.71
CNS 37.24
CPE 8.225
FSCT 29.82
CNXM 17.5
FATE 14.5
LCNB 16.39
LXFT 57.74
FOXA 49.135
WEYS 27.11
EFR 13.07
HEWY 26.63
HDSN 1.18
ALB 80.39
ELLI 74.04
GEN 1.525
WSC 10.19
NFRA 46.6
JXI 50.94
CIG 3.755
DLPN 1.42
FRT 131.53
IAU 12.64
ALDR 14.16
UCBI 26.25
MFA-B 24.77
AQN 10.985
DSM 7.34
IVR-A 24.96
FNLC 26.15
WMC 9.58
CASY 130.35
PCMI 21.22
MOBL 4.82
BSTC 64.66
SSRM 13.71
INSI 18.5
AUTO 3.15
CCR 18.45
GDO 15.98
RDVT 7.75
ON 20.12
SON 56.825
AAME 2.53
USO 11.405
CYH 3.77
CS 12.48
SNV 36.43
VTVT 2.75
IVR-B 25.64
GDV-A 25.72
PSAU 18.91
KIM-L 21.39
EPE 0.7139
HEES 26.47
ISSC 2.25
DEUS 30.62
EV 38.47
USEG 0.871
CLNY-J 20.39
WFC-Q 25.35
IBDQ 24.25
BIP 38.86
HALO 16.23
SCHW 46.98
TOWR 29.55
ADOM 0.2535
IPLDP 24.9
DEX 9.41
CPST 0.8491
TNK 1.015
GRC 33.99
VOOV 105.66
PSCI 60.84
WHLM 5.85
WNEB 9.35
PFFA 23.805
KONA 1.13
AMAG 15.26
AUPH 6.35
YLCO 12.21
DAVA 24.21
CC 36.19
PDFS 10.43
TISA 0.52
AYTU 1.2
FINX 25.08
YVR 2.35
VOC 4.77
UIS 13.06
TMO 245.64
YRCW 5.89
UWN 2.47
TPH 12.66
VERU 1.48
WMB 27.07
XHE 74.61
COWNZ 24.92
MTEX 18.86
ETP-D 24.8
CSU 7.07
HLNE 36.16
DJP 22.57
OXY 67.33
BDC 52.93
DMRS 52.19
CDR-B 24.725
MSA 98.91
DGII 11.47
SAIC 67.91
PMBC 7.94
CIZ 31.45
UPWK 18.98
RMAX 39.5
KALV 17.57
BAX 71.93
CCD 19.35
ICAN 27.41
PRO 34.2
STNLW 0.905
SD 8.29
XNET 3.42
FELP 3.3
ERJ 21.04
DDWM 27.52
RZG 113.33
EMCB 69.57
NCTY 1.37
MMT 5.56
TIF 88.55
BMI 52.56
TOUR 4.48
NS-C 23.86
SLNO 1.72
SBLKZ 25.24
CCMP 102.1
PSC 30.03
XRX 28.22
OMFL 26.45
VLGEA 26.6
DBP 37.16
LTPZ 62.45
IVAC 5.3
XHR 18.68
RWM 42.16
ATHN 134.59
FOE 16.69
CURE 52.53
FPAY 0.79
DRAD 0.7
JMEI 2.635
TNXP 2.01
DRRX 0.6003
IGEB 48.21
SSW-H 23.25
NIU 7.6
FTXD 21.54
BRSS 29.87
OSG 1.895
RMR 66.91
XLU 53.84
NPTN 7.06
AGGP 18.96
SCHF 30.505
DNLI 19.19
DAIO 5.87
HYLB 48.875
REGL 54.95
IDEV 52.47
UMBF 63.29
SLYG 58.31
GRNQ 3.2
PPT 4.965
OAK-B 24.25
CHY 10.995
NOA 10.34
RWW 63.43
LENS 0.44
STN 23.6
MDYV 49.21
DLS 64.93
NESR 7.81
HTLD 20.51
KNL 19.75
JLL 141.87
SBFG 18.4
NAVG 69.79
GSLC 53.87
KBE 43.31
C-N 26.28
RFEU 56.47
CRL 123.12
JILL 6.05
OHGI 0.13
PHT 8.5
MXL 19.37
CERS 5.75
GLMD 7.51
DVD 1.98
HIL 3.36
EMO 9.69
HST 18.25
DVN 27.66
SPXU 37.18
AIMC 30.03
TRT 2.95
NEE 174.47
ROSEW 0.44
FAN 12.58
CENX 8.8
RUBY 13.7
RVSB 7.38
EDD 6.72
VHT 167.69
TNC 58.33
SALM 2.76
CHAP 7.92
LXFR 20.12
ORLY 345.91
RGR 53.72
WGP 32.93
APO-A 24.52
DES 27.13
WSTL 2.16
GFI 4.04
EES 35.57
USMF 27.77
ALD 44.03
AMN 64.62
NEO 16.41
BDC-B 72.16
ALDX 8.67
WOR 37.51
TWOU 56.82
PFL 11.32
AGCO 64.38
MGA 52.59
BKK 14.93
CEI 0.467
EPHE 34.77
AVAL 6.81
DWSH 25.56
AFIF 9.94
BPFH 11.8
ACRE 14.36
IYH 188.98
PBE 51.69
TEL 80.37
PRCP 8.13
DRN 22.45
SPOK 13.8
EDV 112.26
BWA 40.71
PAHC 31.23
SCOR 19.53
EOT 20.74
EXFO 3.28
STL-A 26.5
VRSK 118.38
FLR 36.475
ALLT 6.75
EPR 72.6
HTY 6.92
CBH 8.75
ICLR 139.39
RFDI 55.83
TECS 21.6
DD-B 99.9
CABO 857.52
QUOT 10.06
SPB 54.89
UAL 87.53
PRTA 11.78
NWFL 29.37
LYV 53.18
AFSI-C 8.3
NPV 12.04
HEQ 14.36
ARNC 18.83
VSEC 32.5
AME 72.86
KMT 38.3
PRTO 2.58
JG 7.71
BAH 48.5
MOXC 0.5498
MTUM 105.93
REGI 28.19
GLTR 65.06
FULT 16.355
PSJ 81.75
NUV 9.625
CI 199.92
ANH 4.495
ACER 24.25
CYTR 0.5675
ATSG 23.51
JKE 170.56
ENB 36.77
IPHS 30.15
VIXM 24.26
FLWS 13.16
BLMT 33.01
C-K 26.75
IESC 16.65
ATISW 0.08
APDN 0.459
VRTS 87.03
IQLT 27.53
SPXC 29.25
EVFM 3.43
INDL 60.71
DTV 53.49
PYPL 93.2
DCOM 19.73
EVA 30.36
FCBP 21.25
TDE 24.99
GRA 71.58
EPC 39.01
JAKK 1.82
ASTC 5.01
BSE 12.43
UG 19.44
DATA 128.58
FN 55.21
COUP 79.98
CTRN 20.71
DOG 56.93
ERF 8.93
DXF 3.02
ENT 2.595
GSBD 20.34
ZSAN 2.45
PDEX 14.45
FOLD 11.54
JAZZ 125.77
TRTX 19.57
SFST 37.02
PAGG 25.64
BSCE 25.15
PZD 40.03
FTFT 0.79
ZG 33.68
SCO 20.51
HOFT 28.41
KGJI 0.756
SPUU 46.66
NRT 6.3
SOLOW 0.4
KOP 23.18
KRC 70.35
FLM 49.03
JDST 39.45
IGOV 49.17
CVLY 22.48
TTS 7.59
WBC 113.955
COWN 15.74
FTSV 14.56
MITT 17.9
NXJ 13.175
RWR 95.2
CHMG 42.17
GASL 8.44
RJI 5.24
TENB 27.0
BRACR 0.32
AIHS 3.95
MSI 117.01
WBIG 23.34
MARPS 2.02
IPG 22.79
JPI 21.95
MSCI 163.26
RNR 137.54
ETON 6.2
FEX 56.65
MS-K 25.44
PLND 17.14
HSDT 7.49
MLM 179.1
SRV 9.88
TRI 51.99
STND 31.2
HUBG 44.54
EDRY 7.61
LLL 199.87
IYF 116.59
EXTR 7.445
CORT 11.81
NSP 105.65
GLP 19.35
CHSCP 29.0
BGIO 8.75
ENOB 6.215
HL 2.61
PHCF 4.9
TRQ 1.685
DFFN 2.16
SEND 50.34
CCOI 47.51
MIDU 37.07
KNX 33.16
TAIT 1.97
MODN 14.31
KMB 108.58
HYHG 65.32
APM 13.8
OKTA 79.6
HYLS 46.78
ARTNA 34.59
IGSB 52.17
NULG 32.16
FIF 14.96
EAB 24.22
DLTR 96.49
RETA 76.91
ECOL 63.57
MPB 23.43
CTL 15.1
ALTY 14.57
NAII 11.04
MBOT 8.48
FDUSL 25.45
TVTY 22.12
BFR 13.59
ATOM 3.94
NOC 282.09
LRET 24.5
CMFNL 25.19
VTSI 4.0
SBUX 68.145
FMAO 30.98
MITT-B 25.315
FET 5.035
EWH 24.52
NTRS 90.01
SDIV 19.13
SONO 11.55
CHN 19.01
VLRS 7.45
SLY 65.71
STL 19.58
AGYS 17.78
FAM 9.94
NCLH 51.12
ULH 20.47
ALG 86.55
NNVC 0.3009
THRM 41.32
BAF 13.27
UTSL 27.47
EZT 25.52
BH 130.25
EDZ 45.0
GLW 33.725
WWE 83.65
MORT 23.13
TRK 15.97
SRG-A 23.25
SRC 39.14
FCNCA 413.94
BHK 12.92
TRGP 43.33
SBNY 127.57
CWK 16.43
ET 14.63
WPG-I 15.24
TWMC 0.63
SIGA 6.66
TYD 42.81
EARS 0.43
FREL 24.81
FNY 40.34
SMMF 23.26
SPG 182.22
SNN 37.99
NBN 19.98
SSNC 50.73
CNP-B 52.58
THFF 41.81
IYR 82.93
AMH-F 22.69
INFU 3.75
NGVC 13.4
NEWTI 25.58
AGRX 0.8225
BB 8.115
FSM 3.9
VGZ 0.67
HWKN 42.2
SNBR 35.65
ITCB 14.82
PB 72.31
AOS 47.83
SRTY 28.76
MOSY 0.1799
IBDR 23.54
DEMG 24.78
VRRM 10.34
IAI 60.85
OPNT 14.725
FIEE 136.35
LUV 57.53
POOL 150.51
APPN 31.59
REV 25.55
EYES 0.81
AEO 21.285
MEIP 2.68
CFBI 10.66
TYME 2.75
NOMD 18.03
NWE 63.09
BSJN 25.55
BIF 10.71
DPST 47.52
BHVN 38.27
ROAN 10.78
SKIS 4.55
DFS 67.98
BCS 8.54
KSA 32.03
PSA-E 22.17
OSMT 7.89
MYE 16.24
SAR 23.21
LOGC 8.68
AMRX 11.95
SELF 3.97
STAR 9.66
GMLP 13.23
BOLD 23.72
JPEM 53.95
BOCH 10.97
OPINI 23.65
NRIM 33.14
IOSP 69.72
MCRB 6.19
HABT 10.24
MRC 15.77
SWP 94.87
NVGS 9.45
TAN 22.51
CDAY 40.49
KALA 5.35
CKPT 3.8
VVR 4.085
CEA 30.75
AXTI 4.06
WSBC 41.72
BMLP 47.2
FRC-D 24.16
DBX 23.95
HCFT 3.37
TD 56.21
GWRS 9.62
MGP 30.79
PIHPP 22.37
XHB 36.14
DDIV 22.95
CVM 2.87
LONE 4.85
GLO 9.15
PFI 31.08
HYAC 10.17
BOMN 24.96
FMN 13.03
BOKF 85.98
FWONK 30.73
MASI 123.62
IEF 104.28
AIG+ 7.02
